
Running tests... 
----------------------------------------------------------------------
 test_1 (test_planday.TestPayday) ... ERROR (0.000000)s
 test_2 (test_planday.TestPayday) ... ERROR (0.000000)s
 test_3 (test_planday.TestPayday) ... ERROR (0.000000)s
 test_4_and_5 (test_planday.TestPayday) ... ERROR (0.000000)s
 test_6_and_7_and_8 (test_planday.TestPayday) ... ERROR (0.000000)s

======================================================================
ERROR [0.000000s]: test_planday.TestPayday.test_1
----------------------------------------------------------------------
Traceback (most recent call last):
  File "lib\site-packages\selenium\webdriver\common\service.py", line 76, in start
  File "subprocess.py", line 775, in __init__
  File "subprocess.py", line 1178, in _execute_child
FileNotFoundError: [WinError 2] The system cannot find the file specified

During handling of the above exception, another exception occurred:

Traceback (most recent call last):
  File "test_planday.py", line 17, in setUp
    self.driver = webdriver.Firefox(executable_path=executable_path)
  File "lib\site-packages\selenium\webdriver\firefox\webdriver.py", line 164, in __init__
  File "lib\site-packages\selenium\webdriver\common\service.py", line 83, in start
selenium.common.exceptions.WebDriverException: Message: 'geckodriver.exe' executable needs to be in PATH. 


======================================================================
ERROR [0.000000s]: test_planday.TestPayday.test_2
----------------------------------------------------------------------
Traceback (most recent call last):
  File "lib\site-packages\selenium\webdriver\common\service.py", line 76, in start
  File "subprocess.py", line 775, in __init__
  File "subprocess.py", line 1178, in _execute_child
FileNotFoundError: [WinError 2] The system cannot find the file specified

During handling of the above exception, another exception occurred:

Traceback (most recent call last):
  File "test_planday.py", line 17, in setUp
    self.driver = webdriver.Firefox(executable_path=executable_path)
  File "lib\site-packages\selenium\webdriver\firefox\webdriver.py", line 164, in __init__
  File "lib\site-packages\selenium\webdriver\common\service.py", line 83, in start
selenium.common.exceptions.WebDriverException: Message: 'geckodriver.exe' executable needs to be in PATH. 


======================================================================
ERROR [0.000000s]: test_planday.TestPayday.test_3
----------------------------------------------------------------------
Traceback (most recent call last):
  File "lib\site-packages\selenium\webdriver\common\service.py", line 76, in start
  File "subprocess.py", line 775, in __init__
  File "subprocess.py", line 1178, in _execute_child
FileNotFoundError: [WinError 2] The system cannot find the file specified

During handling of the above exception, another exception occurred:

Traceback (most recent call last):
  File "test_planday.py", line 17, in setUp
    self.driver = webdriver.Firefox(executable_path=executable_path)
  File "lib\site-packages\selenium\webdriver\firefox\webdriver.py", line 164, in __init__
  File "lib\site-packages\selenium\webdriver\common\service.py", line 83, in start
selenium.common.exceptions.WebDriverException: Message: 'geckodriver.exe' executable needs to be in PATH. 


======================================================================
ERROR [0.000000s]: test_planday.TestPayday.test_4_and_5
----------------------------------------------------------------------
Traceback (most recent call last):
  File "lib\site-packages\selenium\webdriver\common\service.py", line 76, in start
  File "subprocess.py", line 775, in __init__
  File "subprocess.py", line 1178, in _execute_child
FileNotFoundError: [WinError 2] The system cannot find the file specified

During handling of the above exception, another exception occurred:

Traceback (most recent call last):
  File "test_planday.py", line 17, in setUp
    self.driver = webdriver.Firefox(executable_path=executable_path)
  File "lib\site-packages\selenium\webdriver\firefox\webdriver.py", line 164, in __init__
  File "lib\site-packages\selenium\webdriver\common\service.py", line 83, in start
selenium.common.exceptions.WebDriverException: Message: 'geckodriver.exe' executable needs to be in PATH. 


======================================================================
ERROR [0.000000s]: test_planday.TestPayday.test_6_and_7_and_8
----------------------------------------------------------------------
Traceback (most recent call last):
  File "lib\site-packages\selenium\webdriver\common\service.py", line 76, in start
  File "subprocess.py", line 775, in __init__
  File "subprocess.py", line 1178, in _execute_child
FileNotFoundError: [WinError 2] The system cannot find the file specified

During handling of the above exception, another exception occurred:

Traceback (most recent call last):
  File "test_planday.py", line 17, in setUp
    self.driver = webdriver.Firefox(executable_path=executable_path)
  File "lib\site-packages\selenium\webdriver\firefox\webdriver.py", line 164, in __init__
  File "lib\site-packages\selenium\webdriver\common\service.py", line 83, in start
selenium.common.exceptions.WebDriverException: Message: 'geckodriver.exe' executable needs to be in PATH. 


----------------------------------------------------------------------
Ran 5 tests in 0:00:00

FAILED
 (Errors=5)

Generating HTML reports... 
